<?xml version="1.0" encoding="utf-8"?>
<!-- This URDF was automatically created by SolidWorks to URDF Exporter! Originally created by Stephen Brawner (brawner@gmail.com) 
     Commit Version: 1.6.0-4-g7f85cfe  Build Version: 1.6.7995.38578
     For more information, please see http://wiki.ros.org/sw_urdf_exporter -->
<robot
  name="service_robot">
  <link
    name="base_link">
    <inertial>
      <origin
        xyz="-0.0031459 0.0033139 0.64916"
        rpy="0 0 0" />
      <mass
        value="42.124" />
      <inertia
        ixx="4.8432"
        ixy="-1.579E-05"
        ixz="0.11714"
        iyy="3.0932"
        iyz="9.31E-07"
        izz="2.5052" />
    </inertial>
    <visual>
      <origin
        xyz="0 0 0"
        rpy="0 0 0" />
      <geometry>
        <mesh
          filename="package://service_robot/meshes/base_link.STL" />
      </geometry>
      <material
        name="">
        <color
          rgba="0.79216 0.81961 0.93333 1" />
      </material>
    </visual>
    <collision>
      <origin
        xyz="0 0 0"
        rpy="0 0 0" />
      <geometry>
        <mesh
          filename="package://service_robot/meshes/base_link.STL" />
      </geometry>
    </collision>
  </link>
  <link
    name="right_wheel_link">
    <inertial>
      <origin
        xyz="-8.5696E-06 -0.014377 -4.2287E-06"
        rpy="0 0 0" />
      <mass
        value="0.23049" />
      <inertia
        ixx="0.00040755"
        ixy="-2.6813E-08"
        ixz="7.4014E-09"
        iyy="0.00077146"
        iyz="-1.2711E-08"
        izz="0.00040754" />
    </inertial>
    <visual>
      <origin
        xyz="0 0 0"
        rpy="0 0 0" />
      <geometry>
        <mesh
          filename="package://service_robot/meshes/right_wheel_link.STL" />
      </geometry>
      <material
        name="">
        <color
          rgba="0.79216 0.81961 0.93333 1" />
      </material>
    </visual>
    <collision>
      <origin
        xyz="0 0 0"
        rpy="0 0 0" />
      <geometry>
        <mesh
          filename="package://service_robot/meshes/right_wheel_link.STL" />
      </geometry>
    </collision>
  </link>
  <joint
    name="right_wheel_joint"
    type="continuous">
    <origin
      xyz="0.00087678 -0.19668 0.071853"
      rpy="0 0 0" />
    <parent
      link="base_link" />
    <child
      link="right_wheel_link" />
    <axis
      xyz="0 -1 0" />
    <limit
      lower="0"
      upper="6.28"
      effort="30"
      velocity="100" />
    <dynamics
      damping="0.5"
      friction="0.1" />
  </joint>
  <link
    name="left_wheel_link">
    <inertial>
      <origin
        xyz="-8.8335E-06 -0.014377 3.6453E-06"
        rpy="0 0 0" />
      <mass
        value="0.23049" />
      <inertia
        ixx="0.00040755"
        ixy="-2.6969E-08"
        ixz="-5.6048E-09"
        iyy="0.00077146"
        iyz="1.2147E-08"
        izz="0.00040753" />
    </inertial>
    <visual>
      <origin
        xyz="0 0 0"
        rpy="0 0 0" />
      <geometry>
        <mesh
          filename="package://service_robot/meshes/left_wheel_link.STL" />
      </geometry>
      <material
        name="">
        <color
          rgba="0.79216 0.81961 0.93333 1" />
      </material>
    </visual>
    <collision>
      <origin
        xyz="0 0 0"
        rpy="0 0 0" />
      <geometry>
        <mesh
          filename="package://service_robot/meshes/left_wheel_link.STL" />
      </geometry>
    </collision>
  </link>
  <joint
    name="left_wheel_joint"
    type="continuous">
    <origin
      xyz="0.00087678 0.24032 0.071853"
      rpy="0 0 0" />
    <parent
      link="base_link" />
    <child
      link="left_wheel_link" />
    <axis
      xyz="0 1 0" />
    <limit
      lower="0"
      upper="6.28"
      effort="30"
      velocity="100" />
    <dynamics
      damping="0.5"
      friction="0.1" />
  </joint>
  <link
    name="lidar">
    <inertial>
      <origin
        xyz="-0.0228773601981522 2.80630767646173E-05 -0.014854319130004"
        rpy="0 0 0" />
      <mass
        value="0.221560580762791" />
      <inertia
        ixx="0.000164350974205098"
        ixy="-7.73309314852227E-10"
        ixz="4.19289477048433E-06"
        iyy="0.000162484506964497"
        iyz="6.02884100551171E-08"
        izz="0.000107097774798223" />
    </inertial>
    <visual>
      <origin
        xyz="0 0 0"
        rpy="0 0 0" />
      <geometry>
        <mesh
          filename="package://service_robot/meshes/lidar.STL" />
      </geometry>
      <material
        name="">
        <color
          rgba="0.949019607843137 0.949019607843137 0.949019607843137 1" />
      </material>
    </visual>
    <collision>
      <origin
        xyz="0 0 0"
        rpy="0 0 0" />
      <geometry>
        <mesh
          filename="package://service_robot/meshes/lidar.STL" />
      </geometry>
    </collision>
  </link>
  <joint
    name="lidar_joint"
    type="fixed">
    <origin
      xyz="0.26101 0.0028461 0.08675"
      rpy="0 0 0" />
    <parent
      link="base_link" />
    <child
      link="lidar" />
    <axis
      xyz="0 0 0" />
  </joint>
</robot>